docker logs 91b72e63d148c3d3710cb73cf274ee9e400ca2ed7ec319d23d5dd43a28368283
Starting PostgreSQL...
Starting PostgreSQL 15 database server: main.
localhost:5432 - accepting connections
PostgreSQL is ready
Starting Flask application...
[2025-06-13 15:50:27 +0000] [1] [INFO] Starting gunicorn 23.0.0
[2025-06-13 15:50:27 +0000] [1] [INFO] Listening at: http://0.0.0.0:5000 (1)
[2025-06-13 15:50:27 +0000] [1] [INFO] Using worker: sync
[2025-06-13 15:50:27 +0000] [49] [INFO] Booting worker with pid: 49
INFO:chromadb.telemetry.product.posthog:Anonymized telemetry enabled. See                     https://docs.trychroma.com/telemetry for more information.
INFO:chromadb.telemetry.product.posthog:Anonymized telemetry enabled. See                     https://docs.trychroma.com/telemetry for more information.
DEBUG:chromadb.config:Starting component System
DEBUG:chromadb.config:Starting component Posthog
DEBUG:chromadb.config:Starting component System
DEBUG:chromadb.config:Starting component Posthog
ERROR:services.vector_database:Failed to initialize ChromaDB client: error returned from database: (code: 1) table collections already exists
Traceback (most recent call last):
  File "/app/init-database.py", line 9, in <module>
    from main import app
  File "/app/main.py", line 1, in <module>
    from app import app  # noqa: F401
    ^^^^^^^^^^^^^^^^^^^
  File "/app/app.py", line 32, in <module>
    from routes.api_routes import api_bp
  File "/app/routes/api_routes.py", line 9, in <module>
    from services.processed_document_indexer import processed_indexer
  File "/app/services/processed_document_indexer.py", line 169, in <module>
    processed_indexer = ProcessedDocumentIndexer()
                        ^^^^^^^^^^^^^^^^^^^^^^^^^^
  File "/app/services/processed_document_indexer.py", line 21, in __init__
    self.vector_db = VectorDatabase()
                     ^^^^^^^^^^^^^^^^
  File "/app/services/vector_database.py", line 18, in __init__
    self._initialize_client()
  File "/app/services/vector_database.py", line 27, in _initialize_client
    self.client = chromadb.PersistentClient(path=persist_directory)
                  ^^^^^^^^^^^^^^^^^^^^^^^^^^^^^^^^^^^^^^^^^^^^^^^^^
  File "/usr/local/lib/python3.11/site-packages/chromadb/__init__.py", line 161, in PersistentClient
    return ClientCreator(tenant=tenant, database=database, settings=settings)
           ^^^^^^^^^^^^^^^^^^^^^^^^^^^^^^^^^^^^^^^^^^^^^^^^^^^^^^^^^^^^^^^^^^
  File "/usr/local/lib/python3.11/site-packages/chromadb/api/client.py", line 65, in __init__
    super().__init__(settings=settings)
  File "/usr/local/lib/python3.11/site-packages/chromadb/api/shared_system_client.py", line 19, in __init__
    SharedSystemClient._create_system_if_not_exists(self._identifier, settings)
  File "/usr/local/lib/python3.11/site-packages/chromadb/api/shared_system_client.py", line 32, in _create_system_if_not_exists
    new_system.start()
  File "/usr/local/lib/python3.11/site-packages/chromadb/config.py", line 471, in start
    component.start()
  File "/usr/local/lib/python3.11/site-packages/chromadb/api/rust.py", line 112, in start
    self.bindings = chromadb_rust_bindings.Bindings(
                    ^^^^^^^^^^^^^^^^^^^^^^^^^^^^^^^^
chromadb.errors.InternalError: error returned from database: (code: 1) table collections already exists
INFO:services.vector_database:ChromaDB client initialized successfully
INFO:services.sam_gov_api:SAM.gov API initialized with key: 8fvkSRtpKd...
INFO:services.vector_database:ChromaDB client initialized successfully
INFO:services.ai_analyzer:Using OpenRouter API for AI analysis
INFO:services.vector_database:ChromaDB client initialized successfully
[2025-06-13 15:50:30 +0000] [1] [ERROR] Worker (pid:41) exited with code 1
[2025-06-13 15:50:30 +0000] [1] [ERROR] Worker (pid:41) exited with code 1.
DEBUG:urllib3.connectionpool:Starting new HTTPS connection (1): us.i.posthog.com:443
DEBUG:urllib3.connectionpool:https://us.i.posthog.com:443 "POST /batch/ HTTP/1.1" 200 15